[2024-04-27 23:07:14,126] {taskinstance.py:877} INFO - Dependencies all met for <TaskInstance: hello.hello_task 2022-03-26T00:00:00+00:00 [queued]>
[2024-04-27 23:07:14,503] {taskinstance.py:877} INFO - Dependencies all met for <TaskInstance: hello.hello_task 2022-03-26T00:00:00+00:00 [queued]>
[2024-04-27 23:07:14,585] {taskinstance.py:1068} INFO - 
--------------------------------------------------------------------------------
[2024-04-27 23:07:14,605] {taskinstance.py:1069} INFO - Starting attempt 1 of 2
[2024-04-27 23:07:14,606] {taskinstance.py:1070} INFO - 
--------------------------------------------------------------------------------
[2024-04-27 23:07:41,094] {taskinstance.py:1089} INFO - Executing <Task(PythonOperator): hello_task> on 2022-03-26T00:00:00+00:00
[2024-04-27 23:07:41,174] {standard_task_runner.py:52} INFO - Started process 201 to run task
[2024-04-27 23:07:41,403] {standard_task_runner.py:76} INFO - Running: ['airflow', 'tasks', 'run', 'hello', 'hello_task', '2022-03-26T00:00:00+00:00', '--job-id', '81', '--pool', 'default_pool', '--raw', '--subdir', 'DAGS_FOLDER/hello.py', '--cfg-path', '/tmp/tmp6ehk46oh', '--error-file', '/tmp/tmpczf7j8p3']
[2024-04-27 23:07:41,408] {standard_task_runner.py:77} INFO - Job 81: Subtask hello_task
[2024-04-27 23:07:42,094] {logging_mixin.py:104} INFO - Running <TaskInstance: hello.hello_task 2022-03-26T00:00:00+00:00 [running]> on host 10d8235a57dc
[2024-04-27 23:08:11,712] {base_job.py:222} ERROR - LocalTaskJob heartbeat got an exception
Traceback (most recent call last):
  File "/home/airflow/.local/lib/python3.6/site-packages/sqlalchemy/engine/base.py", line 2336, in _wrap_pool_connect
    return fn()
  File "/home/airflow/.local/lib/python3.6/site-packages/sqlalchemy/pool/base.py", line 364, in connect
    return _ConnectionFairy._checkout(self)
  File "/home/airflow/.local/lib/python3.6/site-packages/sqlalchemy/pool/base.py", line 778, in _checkout
    fairy = _ConnectionRecord.checkout(pool)
  File "/home/airflow/.local/lib/python3.6/site-packages/sqlalchemy/pool/base.py", line 495, in checkout
    rec = pool._do_get()
  File "/home/airflow/.local/lib/python3.6/site-packages/sqlalchemy/pool/impl.py", line 241, in _do_get
    return self._create_connection()
  File "/home/airflow/.local/lib/python3.6/site-packages/sqlalchemy/pool/base.py", line 309, in _create_connection
    return _ConnectionRecord(self)
  File "/home/airflow/.local/lib/python3.6/site-packages/sqlalchemy/pool/base.py", line 440, in __init__
    self.__connect(first_connect_check=True)
  File "/home/airflow/.local/lib/python3.6/site-packages/sqlalchemy/pool/base.py", line 661, in __connect
    pool.logger.debug("Error on connect(): %s", e)
  File "/home/airflow/.local/lib/python3.6/site-packages/sqlalchemy/util/langhelpers.py", line 70, in __exit__
    with_traceback=exc_tb,
  File "/home/airflow/.local/lib/python3.6/site-packages/sqlalchemy/util/compat.py", line 182, in raise_
    raise exception
  File "/home/airflow/.local/lib/python3.6/site-packages/sqlalchemy/pool/base.py", line 656, in __connect
    connection = pool._invoke_creator(self)
  File "/home/airflow/.local/lib/python3.6/site-packages/sqlalchemy/engine/strategies.py", line 114, in connect
    return dialect.connect(*cargs, **cparams)
  File "/home/airflow/.local/lib/python3.6/site-packages/sqlalchemy/engine/default.py", line 508, in connect
    return self.dbapi.connect(*cargs, **cparams)
  File "/home/airflow/.local/lib/python3.6/site-packages/psycopg2/__init__.py", line 127, in connect
    conn = _connect(dsn, connection_factory=connection_factory, **kwasync)
psycopg2.OperationalError: could not translate host name "postgres" to address: Temporary failure in name resolution


The above exception was the direct cause of the following exception:

Traceback (most recent call last):
  File "/home/airflow/.local/lib/python3.6/site-packages/airflow/jobs/base_job.py", line 194, in heartbeat
    session.merge(self)
  File "/home/airflow/.local/lib/python3.6/site-packages/sqlalchemy/orm/session.py", line 2171, in merge
    _resolve_conflict_map=_resolve_conflict_map,
  File "/home/airflow/.local/lib/python3.6/site-packages/sqlalchemy/orm/session.py", line 2244, in _merge
    merged = self.query(mapper.class_).get(key[1])
  File "/home/airflow/.local/lib/python3.6/site-packages/sqlalchemy/orm/query.py", line 1018, in get
    return self._get_impl(ident, loading.load_on_pk_identity)
  File "/home/airflow/.local/lib/python3.6/site-packages/sqlalchemy/orm/query.py", line 1135, in _get_impl
    return db_load_fn(self, primary_key_identity)
  File "/home/airflow/.local/lib/python3.6/site-packages/sqlalchemy/orm/loading.py", line 286, in load_on_pk_identity
    return q.one()
  File "/home/airflow/.local/lib/python3.6/site-packages/sqlalchemy/orm/query.py", line 3490, in one
    ret = self.one_or_none()
  File "/home/airflow/.local/lib/python3.6/site-packages/sqlalchemy/orm/query.py", line 3459, in one_or_none
    ret = list(self)
  File "/home/airflow/.local/lib/python3.6/site-packages/sqlalchemy/orm/query.py", line 3535, in __iter__
    return self._execute_and_instances(context)
  File "/home/airflow/.local/lib/python3.6/site-packages/sqlalchemy/orm/query.py", line 3557, in _execute_and_instances
    querycontext, self._connection_from_session, close_with_result=True
  File "/home/airflow/.local/lib/python3.6/site-packages/sqlalchemy/orm/query.py", line 3572, in _get_bind_args
    mapper=self._bind_mapper(), clause=querycontext.statement, **kw
  File "/home/airflow/.local/lib/python3.6/site-packages/sqlalchemy/orm/query.py", line 3550, in _connection_from_session
    conn = self.session.connection(**kw)
  File "/home/airflow/.local/lib/python3.6/site-packages/sqlalchemy/orm/session.py", line 1145, in connection
    execution_options=execution_options,
  File "/home/airflow/.local/lib/python3.6/site-packages/sqlalchemy/orm/session.py", line 1151, in _connection_for_bind
    engine, execution_options
  File "/home/airflow/.local/lib/python3.6/site-packages/sqlalchemy/orm/session.py", line 433, in _connection_for_bind
    conn = bind._contextual_connect()
  File "/home/airflow/.local/lib/python3.6/site-packages/sqlalchemy/engine/base.py", line 2302, in _contextual_connect
    self._wrap_pool_connect(self.pool.connect, None),
  File "/home/airflow/.local/lib/python3.6/site-packages/sqlalchemy/engine/base.py", line 2340, in _wrap_pool_connect
    e, dialect, self
  File "/home/airflow/.local/lib/python3.6/site-packages/sqlalchemy/engine/base.py", line 1584, in _handle_dbapi_exception_noconnection
    sqlalchemy_exception, with_traceback=exc_info[2], from_=e
  File "/home/airflow/.local/lib/python3.6/site-packages/sqlalchemy/util/compat.py", line 182, in raise_
    raise exception
  File "/home/airflow/.local/lib/python3.6/site-packages/sqlalchemy/engine/base.py", line 2336, in _wrap_pool_connect
    return fn()
  File "/home/airflow/.local/lib/python3.6/site-packages/sqlalchemy/pool/base.py", line 364, in connect
    return _ConnectionFairy._checkout(self)
  File "/home/airflow/.local/lib/python3.6/site-packages/sqlalchemy/pool/base.py", line 778, in _checkout
    fairy = _ConnectionRecord.checkout(pool)
  File "/home/airflow/.local/lib/python3.6/site-packages/sqlalchemy/pool/base.py", line 495, in checkout
    rec = pool._do_get()
  File "/home/airflow/.local/lib/python3.6/site-packages/sqlalchemy/pool/impl.py", line 241, in _do_get
    return self._create_connection()
  File "/home/airflow/.local/lib/python3.6/site-packages/sqlalchemy/pool/base.py", line 309, in _create_connection
    return _ConnectionRecord(self)
  File "/home/airflow/.local/lib/python3.6/site-packages/sqlalchemy/pool/base.py", line 440, in __init__
    self.__connect(first_connect_check=True)
  File "/home/airflow/.local/lib/python3.6/site-packages/sqlalchemy/pool/base.py", line 661, in __connect
    pool.logger.debug("Error on connect(): %s", e)
  File "/home/airflow/.local/lib/python3.6/site-packages/sqlalchemy/util/langhelpers.py", line 70, in __exit__
    with_traceback=exc_tb,
  File "/home/airflow/.local/lib/python3.6/site-packages/sqlalchemy/util/compat.py", line 182, in raise_
    raise exception
  File "/home/airflow/.local/lib/python3.6/site-packages/sqlalchemy/pool/base.py", line 656, in __connect
    connection = pool._invoke_creator(self)
  File "/home/airflow/.local/lib/python3.6/site-packages/sqlalchemy/engine/strategies.py", line 114, in connect
    return dialect.connect(*cargs, **cparams)
  File "/home/airflow/.local/lib/python3.6/site-packages/sqlalchemy/engine/default.py", line 508, in connect
    return self.dbapi.connect(*cargs, **cparams)
  File "/home/airflow/.local/lib/python3.6/site-packages/psycopg2/__init__.py", line 127, in connect
    conn = _connect(dsn, connection_factory=connection_factory, **kwasync)
sqlalchemy.exc.OperationalError: (psycopg2.OperationalError) could not translate host name "postgres" to address: Temporary failure in name resolution

(Background on this error at: http://sqlalche.me/e/13/e3q8)
[2024-04-27 23:09:14,122] {taskinstance.py:1283} INFO - Exporting the following env vars:
AIRFLOW_CTX_DAG_OWNER=airflow
AIRFLOW_CTX_DAG_ID=hello
AIRFLOW_CTX_TASK_ID=hello_task
AIRFLOW_CTX_EXECUTION_DATE=2022-03-26T00:00:00+00:00
AIRFLOW_CTX_DAG_RUN_ID=scheduled__2022-03-26T00:00:00+00:00
[2024-04-27 23:09:14,178] {python.py:118} INFO - Done. Returned value was: Hello Airflow!
[2024-04-27 23:09:14,371] {taskinstance.py:1192} INFO - Marking task as SUCCESS. dag_id=hello, task_id=hello_task, execution_date=20220326T000000, start_date=20240427T230714, end_date=20240427T230914
[2024-04-27 23:09:14,577] {taskinstance.py:1246} INFO - 1 downstream tasks scheduled from follow-on schedule check
[2024-04-27 23:09:14,765] {local_task_job.py:146} INFO - Task exited with return code 0
